Workbook

Sheet Oversigt
A1: D&D 2024 – udstyrsoversigt
A2: Data kopieret fra D&D Beyond (Player's Handbook, Dungeon Master's Guide og D&D Beyond Basic Rules). Alle tal på dette ark beregnes med formler ud fra arket 'Alle items'.
A3: Pris (GP) omregner 1 SP = 0,1 GP og 1 CP = 0,01 GP. Tomme felter betyder, at kilden ikke angiver en pris/vægt (fx moderne våben).
A4: Arkene 'Våben' og 'Rustning' er udsnit af de samme rækker.
A6: Antal og pris pr. gruppe
A7: Gruppe | B7: Antal | C7: Billigste (GP) | D7: Dyreste (GP) | E7: Gns. pris (GP) | I7: 0 | J7: Udstyr | K7: Ammunition | L7: Fokus | M7: Våben | N7: Rustning | O7: Gift | P7: Værktøj
A8: Ammunition | B8: =COUNTIF('Alle items'!$C$2:$C$216,$A8) -> 4 | C8: =IFERROR(_xlfn.MINIFS('Alle items'!$G$2:$G$216,'Alle items'!$C$2:$C$216,$A8),"") -> 0.04 | D8: =IFERROR(_xlfn.MAXIFS('Alle items'!$G$2:$G$216,'Alle items'!$C$2:$C$216,$A8),"") -> 3 | E8: =IFERROR(AVERAGEIF('Alle items'!$C$2:$C$216,$A8,'Alle items'!$G$2:$G$216),"") -> 1.3466667 | H8: Common | I8: 2 | J8: =COUNTIFS('Alle items'!$C:$C,J$7,'Alle items'!$G:$G,">"&$I7,'Alle items'!$G:$G,"<="&$I8) -> 38 | K8: =COUNTIFS('Alle items'!$C:$C,K$7,'Alle items'!$G:$G,">"&$I7,'Alle items'!$G:$G,"<="&$I8) -> 2 | L8: =COUNTIFS('Alle items'!$C:$C,L$7,'Alle items'!$G:$G,">"&$I7,'Alle items'!$G:$G,"<="&$I8) -> 1 | M8: =COUNTIFS('Alle items'!$C:$C,M$7,'Alle items'!$G:$G,">"&$I7,'Alle items'!$G:$G,"<="&$I8) -> 12 | N8: =COUNTIFS('Alle items'!$C:$C,N$7,'Alle items'!$G:$G,">"&$I7,'Alle items'!$G:$G,"<="&$I8) -> 0 | O8: =COUNTIFS('Alle items'!$C:$C,O$7,'Alle items'!$G:$G,">"&$I7,'Alle items'!$G:$G,"<="&$I8) -> 0 | P8: =COUNTIFS('Alle items'!$C:$C,P$7,'Alle items'!$G:$G,">"&$I7,'Alle items'!$G:$G,"<="&$I8) -> 9 | Q8: =SUM(J8:P8) -> 62 | T8: Magic Item
A9: Fokus | B9: =COUNTIF('Alle items'!$C$2:$C$216,$A9) -> 12 | C9: =IFERROR(_xlfn.MINIFS('Alle items'!$G$2:$G$216,'Alle items'!$C$2:$C$216,$A9),"") -> 1 | D9: =IFERROR(_xlfn.MAXIFS('Alle items'!$G$2:$G$216,'Alle items'!$C$2:$C$216,$A9),"") -> 20 | E9: =IFERROR(AVERAGEIF('Alle items'!$C$2:$C$216,$A9,'Alle items'!$G$2:$G$216),"") -> 8.1 | H9: Uncommon | I9: 10 | J9: =COUNTIFS('Alle items'!$C:$C,J$7,'Alle items'!$G:$G,">"&$I8,'Alle items'!$G:$G,"<="&$I9) -> 13 | K9: =COUNTIFS('Alle items'!$C:$C,K$7,'Alle items'!$G:$G,">"&$I8,'Alle items'!$G:$G,"<="&$I9) -> 1 | L9: =COUNTIFS('Alle items'!$C:$C,L$7,'Alle items'!$G:$G,">"&$I8,'Alle items'!$G:$G,"<="&$I9) -> 8 | M9: =COUNTIFS('Alle items'!$C:$C,M$7,'Alle items'!$G:$G,">"&$I8,'Alle items'!$G:$G,"<="&$I9) -> 9 | N9: =COUNTIFS('Alle items'!$C:$C,N$7,'Alle items'!$G:$G,">"&$I8,'Alle items'!$G:$G,"<="&$I9) -> 4 | O9: =COUNTIFS('Alle items'!$C:$C,O$7,'Alle items'!$G:$G,">"&$I8,'Alle items'!$G:$G,"<="&$I9) -> 0 | P9: =COUNTIFS('Alle items'!$C:$C,P$7,'Alle items'!$G:$G,">"&$I8,'Alle items'!$G:$G,"<="&$I9) -> 10 | Q9: =SUM(J9:P9) -> 45 | T9: Common | U9: 100 | V9: =$U$13/U9 -> 2000 | W9: Common | X9: =100-SUM(X10:X13) -> 54
A10: Gift | B10: =COUNTIF('Alle items'!$C$2:$C$216,$A10) -> 13 | C10: =IFERROR(_xlfn.MINIFS('Alle items'!$G$2:$G$216,'Alle items'!$C$2:$C$216,$A10),"") -> 150 | D10: =IFERROR(_xlfn.MAXIFS('Alle items'!$G$2:$G$216,'Alle items'!$C$2:$C$216,$A10),"") -> 2000 | E10: =IFERROR(AVERAGEIF('Alle items'!$C$2:$C$216,$A10,'Alle items'!$G$2:$G$216),"") -> 596.15385 | H10: Rare | I10: 40 | J10: =COUNTIFS('Alle items'!$C:$C,J$7,'Alle items'!$G:$G,">"&$I9,'Alle items'!$G:$G,"<="&$I10) -> 7 | K10: =COUNTIFS('Alle items'!$C:$C,K$7,'Alle items'!$G:$G,">"&$I9,'Alle items'!$G:$G,"<="&$I10) -> 0 | L10: =COUNTIFS('Alle items'!$C:$C,L$7,'Alle items'!$G:$G,">"&$I9,'Alle items'!$G:$G,"<="&$I10) -> 1 | M10: =COUNTIFS('Alle items'!$C:$C,M$7,'Alle items'!$G:$G,">"&$I9,'Alle items'!$G:$G,"<="&$I10) -> 10 | N10: =COUNTIFS('Alle items'!$C:$C,N$7,'Alle items'!$G:$G,">"&$I9,'Alle items'!$G:$G,"<="&$I10) -> 1 | O10: =COUNTIFS('Alle items'!$C:$C,O$7,'Alle items'!$G:$G,">"&$I9,'Alle items'!$G:$G,"<="&$I10) -> 0 | P10: =COUNTIFS('Alle items'!$C:$C,P$7,'Alle items'!$G:$G,">"&$I9,'Alle items'!$G:$G,"<="&$I10) -> 14 | Q10: =SUM(J10:P10) -> 33 | T10: Uncommon | U10: 400 | V10: =$U$13/U10 -> 500 | W10: Uncommon | X10: 25
A11: Køretøj | B11: =COUNTIF('Alle items'!$C$2:$C$216,$A11) -> 11 | C11: =IFERROR(_xlfn.MINIFS('Alle items'!$G$2:$G$216,'Alle items'!$C$2:$C$216,$A11),"") -> 15 | D11: =IFERROR(_xlfn.MAXIFS('Alle items'!$G$2:$G$216,'Alle items'!$C$2:$C$216,$A11),"") -> 250 | E11: =IFERROR(AVERAGEIF('Alle items'!$C$2:$C$216,$A11,'Alle items'!$G$2:$G$216),"") -> 84 | H11: Very Rare | I11: 250 | J11: =COUNTIFS('Alle items'!$C:$C,J$7,'Alle items'!$G:$G,">"&$I10,'Alle items'!$G:$G,"<="&$I11) -> 5 | K11: =COUNTIFS('Alle items'!$C:$C,K$7,'Alle items'!$G:$G,">"&$I10,'Alle items'!$G:$G,"<="&$I11) -> 0 | L11: =COUNTIFS('Alle items'!$C:$C,L$7,'Alle items'!$G:$G,">"&$I10,'Alle items'!$G:$G,"<="&$I11) -> 0 | M11: =COUNTIFS('Alle items'!$C:$C,M$7,'Alle items'!$G:$G,">"&$I10,'Alle items'!$G:$G,"<="&$I11) -> 5 | N11: =COUNTIFS('Alle items'!$C:$C,N$7,'Alle items'!$G:$G,">"&$I10,'Alle items'!$G:$G,"<="&$I11) -> 6 | O11: =COUNTIFS('Alle items'!$C:$C,O$7,'Alle items'!$G:$G,">"&$I10,'Alle items'!$G:$G,"<="&$I11) -> 6 | P11: =COUNTIFS('Alle items'!$C:$C,P$7,'Alle items'!$G:$G,">"&$I10,'Alle items'!$G:$G,"<="&$I11) -> 2 | Q11: =SUM(J11:P11) -> 24 | T11: Rare | U11: 4000 | V11: =$U$13/U11 -> 50 | W11: Rare | X11: 15
A12: Pakke | B12: =COUNTIF('Alle items'!$C$2:$C$216,$A12) -> 7 | C12: =IFERROR(_xlfn.MINIFS('Alle items'!$G$2:$G$216,'Alle items'!$C$2:$C$216,$A12),"") -> 10 | D12: =IFERROR(_xlfn.MAXIFS('Alle items'!$G$2:$G$216,'Alle items'!$C$2:$C$216,$A12),"") -> 40 | E12: =IFERROR(AVERAGEIF('Alle items'!$C$2:$C$216,$A12,'Alle items'!$G$2:$G$216),"") -> 27.142857 | H12: Legendary | I12: 2500 | J12: =COUNTIFS('Alle items'!$C:$C,J$7,'Alle items'!$G:$G,">"&$I11) -> 1 | K12: =COUNTIFS('Alle items'!$C:$C,K$7,'Alle items'!$G:$G,">"&$I11) -> 0 | L12: =COUNTIFS('Alle items'!$C:$C,L$7,'Alle items'!$G:$G,">"&$I11) -> 0 | M12: =COUNTIFS('Alle items'!$C:$C,M$7,'Alle items'!$G:$G,">"&$I11) -> 1 | N12: =COUNTIFS('Alle items'!$C:$C,N$7,'Alle items'!$G:$G,">"&$I11) -> 3 | O12: =COUNTIFS('Alle items'!$C:$C,O$7,'Alle items'!$G:$G,">"&$I11) -> 7 | P12: =COUNTIFS('Alle items'!$C:$C,P$7,'Alle items'!$G:$G,">"&$I11) -> 0 | Q12: =SUM(J12:P12) -> 12 | T12: Very Rare | U12: 40000 | V12: =$U$13/U12 -> 5 | W12: Very Rare | X12: 5
A13: Ridedyr | B13: =COUNTIF('Alle items'!$C$2:$C$216,$A13) -> 8 | C13: =IFERROR(_xlfn.MINIFS('Alle items'!$G$2:$G$216,'Alle items'!$C$2:$C$216,$A13),"") -> 8 | D13: =IFERROR(_xlfn.MAXIFS('Alle items'!$G$2:$G$216,'Alle items'!$C$2:$C$216,$A13),"") -> 400 | E13: =IFERROR(AVERAGEIF('Alle items'!$C$2:$C$216,$A13,'Alle items'!$G$2:$G$216),"") -> 104.75 | T13: Legendary | U13: 200000 | V13: =$U$13/U13 -> 1 | W13: Legendary | X13: 1
A14: Rustning | B14: =COUNTIF('Alle items'!$C$2:$C$216,$A14) -> 14 | C14: =IFERROR(_xlfn.MINIFS('Alle items'!$G$2:$G$216,'Alle items'!$C$2:$C$216,$A14),"") -> 5 | D14: =IFERROR(_xlfn.MAXIFS('Alle items'!$G$2:$G$216,'Alle items'!$C$2:$C$216,$A14),"") -> 1500 | E14: =IFERROR(AVERAGEIF('Alle items'!$C$2:$C$216,$A14,'Alle items'!$G$2:$G$216),"") -> 229.28571 | T14: Artifact | U14: Priceless
A15: Udstyr | B15: =COUNTIF('Alle items'!$C$2:$C$216,$A15) -> 67 | C15: =IFERROR(_xlfn.MINIFS('Alle items'!$G$2:$G$216,'Alle items'!$C$2:$C$216,$A15),"") -> 0.01 | D15: =IFERROR(_xlfn.MAXIFS('Alle items'!$G$2:$G$216,'Alle items'!$C$2:$C$216,$A15),"") -> 1000 | E15: =IFERROR(AVERAGEIF('Alle items'!$C$2:$C$216,$A15,'Alle items'!$G$2:$G$216),"") -> 28.798281
A16: Våben | B16: =COUNTIF('Alle items'!$C$2:$C$216,$A16) -> 44 | C16: =IFERROR(_xlfn.MINIFS('Alle items'!$G$2:$G$216,'Alle items'!$C$2:$C$216,$A16),"") -> 0.05 | D16: =IFERROR(_xlfn.MAXIFS('Alle items'!$G$2:$G$216,'Alle items'!$C$2:$C$216,$A16),"") -> 500 | E16: =IFERROR(AVERAGEIF('Alle items'!$C$2:$C$216,$A16,'Alle items'!$G$2:$G$216),"") -> 34.193243
A17: Værktøj | B17: =COUNTIF('Alle items'!$C$2:$C$216,$A17) -> 35 | C17: =IFERROR(_xlfn.MINIFS('Alle items'!$G$2:$G$216,'Alle items'!$C$2:$C$216,$A17),"") -> 0.1 | D17: =IFERROR(_xlfn.MAXIFS('Alle items'!$G$2:$G$216,'Alle items'!$C$2:$C$216,$A17),"") -> 50 | E17: =IFERROR(AVERAGEIF('Alle items'!$C$2:$C$216,$A17,'Alle items'!$G$2:$G$216),"") -> 14.674286
A18: I alt | B18: =COUNTA('Alle items'!$A$2:$A$216) -> 215
A21: Antal pr. kilde
A22: Kilde | B22: Antal
A23: D&D Beyond Basic Rules | B23: =COUNTIF('Alle items'!$D$2:$D$216,$A23) -> 50
A24: Dungeon Master's Guide | B24: =COUNTIF('Alle items'!$D$2:$D$216,$A24) -> 27
A25: Player's Handbook | B25: =COUNTIF('Alle items'!$D$2:$D$216,$A25) -> 138
J27: Ridedyr | K27: Køretøj | L27: Pakke
J28: =COUNTIFS('Alle items'!$C:$C,J$27,'Alle items'!$G:$G,">"&$I7,'Alle items'!$G:$G,"<="&$I8) -> 0 | K28: =COUNTIFS('Alle items'!$C:$C,K$27,'Alle items'!$G:$G,">"&$I7,'Alle items'!$G:$G,"<="&$I8) -> 0 | L28: =COUNTIFS('Alle items'!$C:$C,L$27,'Alle items'!$G:$G,">"&$I7,'Alle items'!$G:$G,"<="&$I8) -> 0
A29: Våben pr. mastery-egenskab | J29: =COUNTIFS('Alle items'!$C:$C,J$27,'Alle items'!$G:$G,">"&$I8,'Alle items'!$G:$G,"<="&$I9) -> 1 | K29: =COUNTIFS('Alle items'!$C:$C,K$27,'Alle items'!$G:$G,">"&$I8,'Alle items'!$G:$G,"<="&$I9) -> 0 | L29: =COUNTIFS('Alle items'!$C:$C,L$27,'Alle items'!$G:$G,">"&$I8,'Alle items'!$G:$G,"<="&$I9) -> 1
A30: Mastery | B30: Antal våben | J30: =COUNTIFS('Alle items'!$C:$C,J$27,'Alle items'!$G:$G,">"&$I9,'Alle items'!$G:$G,"<="&$I10) -> 2 | K30: =COUNTIFS('Alle items'!$C:$C,K$27,'Alle items'!$G:$G,">"&$I9,'Alle items'!$G:$G,"<="&$I10) -> 3 | L30: =COUNTIFS('Alle items'!$C:$C,L$27,'Alle items'!$G:$G,">"&$I9,'Alle items'!$G:$G,"<="&$I10) -> 6
A31: Cleave | B31: =COUNTIF('Alle items'!$M$2:$M$216,$A31) -> 2 | J31: =COUNTIFS('Alle items'!$C:$C,J$27,'Alle items'!$G:$G,">"&$I10,'Alle items'!$G:$G,"<="&$I11) -> 4 | K31: =COUNTIFS('Alle items'!$C:$C,K$27,'Alle items'!$G:$G,">"&$I10,'Alle items'!$G:$G,"<="&$I11) -> 2 | L31: =COUNTIFS('Alle items'!$C:$C,L$27,'Alle items'!$G:$G,">"&$I10,'Alle items'!$G:$G,"<="&$I11) -> 0
A32: Graze | B32: =COUNTIF('Alle items'!$M$2:$M$216,$A32) -> 2 | J32: =COUNTIFS('Alle items'!$C:$C,J$27,'Alle items'!$G:$G,">"&$I11) -> 1 | K32: =COUNTIFS('Alle items'!$C:$C,K$27,'Alle items'!$G:$G,">"&$I11) -> 0 | L32: =COUNTIFS('Alle items'!$C:$C,L$27,'Alle items'!$G:$G,">"&$I11) -> 0
A33: Nick | B33: =COUNTIF('Alle items'!$M$2:$M$216,$A33) -> 4
A34: Push | B34: =COUNTIF('Alle items'!$M$2:$M$216,$A34) -> 5
A35: Sap | B35: =COUNTIF('Alle items'!$M$2:$M$216,$A35) -> 7
A36: Slow | B36: =COUNTIF('Alle items'!$M$2:$M$216,$A36) -> 10
A37: Topple | B37: =COUNTIF('Alle items'!$M$2:$M$216,$A37) -> 4
A38: Vex | B38: =COUNTIF('Alle items'!$M$2:$M$216,$A38) -> 9
A42: Antal pr. tag
A43: Tag | B43: Antal
A44: Combat | B44: =SUMPRODUCT(--ISNUMBER(SEARCH($A44,'Alle items'!$Q$2:$Q$216))) -> 51
A45: Communication | B45: =SUMPRODUCT(--ISNUMBER(SEARCH($A45,'Alle items'!$Q$2:$Q$216))) -> 5
A46: Consumable | B46: =SUMPRODUCT(--ISNUMBER(SEARCH($A46,'Alle items'!$Q$2:$Q$216))) -> 7
A47: Container | B47: =SUMPRODUCT(--ISNUMBER(SEARCH($A47,'Alle items'!$Q$2:$Q$216))) -> 21
...

Sheet Alle items
A1: Navn | B1: Kategori | C1: Gruppe | D1: Kilde | E1: Rarity | F1: Pris | G1: Pris (GP) | H1: Vægt | I1: Vægt (lbs) | J1: Skade | K1: Skadetype | L1: Egenskaber | M1: Mastery | N1: AC | O1: Styrkekrav | P1: Stealth | Q1: Tags | R1: Noter | S1: Beskrivelse
A2: Candle | B2: Adventuring Gear | C2: Udstyr | D2: Player's Handbook | E2: =IF(G2<Oversigt!$I$8,Oversigt!$H$8,IF(G2<Oversigt!$I$9,Oversigt!$H$9,IF(G2<Oversigt!$I$10,Oversigt!$H$10,IF(G2<Oversigt!$I$11,Oversigt!$H$11,IF(G2<Oversigt!$I$12,Oversigt!$H$12,Oversigt!$H$13))))) -> Common | F2: 1 CP | G2: 0.01 | Q2: Utility, Exploration, Consumable | S2: For 1 hour, a lit Candle sheds Bright Light in a 5-foot radius and Dim Light for an additional 5 feet.
A3: Sack | B3: Adventuring Gear | C3: Udstyr | D3: Player's Handbook | E3: =IF(G3<Oversigt!$I$8,Oversigt!$H$8,IF(G3<Oversigt!$I$9,Oversigt!$H$9,IF(G3<Oversigt!$I$10,Oversigt!$H$10,IF(G3<Oversigt!$I$11,Oversigt!$H$11,IF(G3<Oversigt!$I$12,Oversigt!$H$12,Oversigt!$H$13))))) -> Common | F3: 1 CP | G3: 0.01 | H3: 1/2 lb | I3: 0.5 | Q3: Container | S3: A Sack holds up to 30 pounds within 1 cubic foot.
A4: Torch | B4: Adventuring Gear | C4: Udstyr | D4: Player's Handbook | E4: =IF(G4<Oversigt!$I$8,Oversigt!$H$8,IF(G4<Oversigt!$I$9,Oversigt!$H$9,IF(G4<Oversigt!$I$10,Oversigt!$H$10,IF(G4<Oversigt!$I$11,Oversigt!$H$11,IF(G4<Oversigt!$I$12,Oversigt!$H$12,Oversigt!$H$13))))) -> Common | F4: 1 CP | G4: 0.01 | H4: 1 lb | I4: 1 | Q4: Damage, Utility, Exploration, Combat | S4: A Torch burns for 1 hour, casting Bright Light in a 20-foot radius and Dim Light for an additional 20 feet. When you take the Attack action, you can attack with the Torch, using it as a Simple Melee weapon. On a hit, the target takes 1 Fire damage.
A5: Flask | B5: Adventuring Gear | C5: Udstyr | D5: Player's Handbook | E5: =IF(G5<Oversigt!$I$8,Oversigt!$H$8,IF(G5<Oversigt!$I$9,Oversigt!$H$9,IF(G5<Oversigt!$I$10,Oversigt!$H$10,IF(G5<Oversigt!$I$11,Oversigt!$H$11,IF(G5<Oversigt!$I$12,Oversigt!$H$12,Oversigt!$H$13))))) -> Common | F5: 2 CP | G5: 0.02 | H5: 1 lb | I5: 1 | Q5: Container | S5: A Flask holds up to 1 pint.
A6: Ink Pen | B6: Adventuring Gear | C6: Udstyr | D6: Player's Handbook | E6: =IF(G6<Oversigt!$I$8,Oversigt!$H$8,IF(G6<Oversigt!$I$9,Oversigt!$H$9,IF(G6<Oversigt!$I$10,Oversigt!$H$10,IF(G6<Oversigt!$I$11,Oversigt!$H$11,IF(G6<Oversigt!$I$12,Oversigt!$H$12,Oversigt!$H$13))))) -> Common | F6: 2 CP | G6: 0.02 | Q6: Communication, Social, Utility | S6: Using Ink, an Ink Pen is used to write or draw.
A7: Jug | B7: Adventuring Gear | C7: Udstyr | D7: Player's Handbook | E7: =IF(G7<Oversigt!$I$8,Oversigt!$H$8,IF(G7<Oversigt!$I$9,Oversigt!$H$9,IF(G7<Oversigt!$I$10,Oversigt!$H$10,IF(G7<Oversigt!$I$11,Oversigt!$H$11,IF(G7<Oversigt!$I$12,Oversigt!$H$12,Oversigt!$H$13))))) -> Common | F7: 2 CP | G7: 0.02 | H7: 4 lbs | I7: 4 | Q7: Container | S7: A Jug holds up to 1 gallon.
A8: Bucket | B8: Adventuring Gear | C8: Udstyr | D8: Player's Handbook | E8: =IF(G8<Oversigt!$I$8,Oversigt!$H$8,IF(G8<Oversigt!$I$9,Oversigt!$H$9,IF(G8<Oversigt!$I$10,Oversigt!$H$10,IF(G8<Oversigt!$I$11,Oversigt!$H$11,IF(G8<Oversigt!$I$12,Oversigt!$H$12,Oversigt!$H$13))))) -> Common | F8: 5 CP | G8: 0.05 | H8: 2 lbs | I8: 2 | Q8: Container | S8: A Bucket holds up to half a cubic foot of contents.
A9: Feed per day | B9: Adventuring Gear | C9: Udstyr | D9: Player's Handbook | E9: =IF(G9<Oversigt!$I$8,Oversigt!$H$8,IF(G9<Oversigt!$I$9,Oversigt!$H$9,IF(G9<Oversigt!$I$10,Oversigt!$H$10,IF(G9<Oversigt!$I$11,Oversigt!$H$11,IF(G9<Oversigt!$I$12,Oversigt!$H$12,Oversigt!$H$13))))) -> Common | F9: 5 CP | G9: 0.05 | H9: 10 lbs | I9: 10 | Q9: Utility, Consumable | S9: Standard feed typically consumed by a mount per day.
A10: Pole | B10: Adventuring Gear | C10: Udstyr | D10: Player's Handbook | E10: =IF(G10<Oversigt!$I$8,Oversigt!$H$8,IF(G10<Oversigt!$I$9,Oversigt!$H$9,IF(G10<Oversigt!$I$10,Oversigt!$H$10,IF(G10<Oversigt!$I$11,Oversigt!$H$11,IF(G10<Oversigt!$I$12,Oversigt!$H$12,Oversigt!$H$13))))) -> Common | F10: 5 CP | G10: 0.05 | H10: 7 lbs | I10: 7 | Q10: Utility, Exploration | S10: A Pole is 10 feet long. You can use it to touch something up to 10 feet away. If you must make a Strength (Athletics) check as part of a High or Long Jump, you can use the Pole to vault, giving yourself Advantage on the check.
A11: Signal Whistle | B11: Adventuring Gear | C11: Udstyr | D11: Player's Handbook | E11: =IF(G11<Oversigt!$I$8,Oversigt!$H$8,IF(G11<Oversigt!$I$9,Oversigt!$H$9,IF(G11<Oversigt!$I$10,Oversigt!$H$10,IF(G11<Oversigt!$I$11,Oversigt!$H$11,IF(G11<Oversigt!$I$12,Oversigt!$H$12,Oversigt!$H$13))))) -> Common | F11: 5 CP | G11: 0.05 | Q11: Communication, Utility | S11: When blown as a Utilize action, a Signal Whistle produces a sound that can be heard up to 600 feet away.
A12: Ladder | B12: Adventuring Gear | C12: Udstyr | D12: Player's Handbook | E12: =IF(G12<Oversigt!$I$8,Oversigt!$H$8,IF(G12<Oversigt!$I$9,Oversigt!$H$9,IF(G12<Oversigt!$I$10,Oversigt!$H$10,IF(G12<Oversigt!$I$11,Oversigt!$H$11,IF(G12<Oversigt!$I$12,Oversigt!$H$12,Oversigt!$H$13))))) -> Common | F12: 1 SP | G12: 0.1 | H12: 25 lbs | I12: 25 | Q12: Utility, Exploration | S12: A Ladder is 10 feet tall. You must climb to move up or down it.
A13: Oil | B13: Adventuring Gear | C13: Udstyr | D13: Player's Handbook | E13: =IF(G13<Oversigt!$I$8,Oversigt!$H$8,IF(G13<Oversigt!$I$9,Oversigt!$H$9,IF(G13<Oversigt!$I$10,Oversigt!$H$10,IF(G13<Oversigt!$I$11,Oversigt!$H$11,IF(G13<Oversigt!$I$12,Oversigt!$H$12,Oversigt!$H$13))))) -> Common | F13: 1 SP | G13: 0.1 | H13: 1 lb | I13: 1 | Q13: Damage, Utility, Combat | S13: You can douse a creature, object, or space with Oil or use it as fuel, as detailed below. Dousing a Creature or an Object. When you take the Attack action, you can replace one of your attacks with throwing an Oil flask. Target one creature or object within 20 feet of yourself. The target must succeed on a Dexterity saving throw (DC 8 plus your Dexterity modifier and Proficiency Bonus) or be covered in oil. If the target takes Fire damage before the oil dries (after 1 minute), the target takes an extra 5 Fire damage from burning oil. Dousing a Space. You can take the Utilize action to pour an Oil flask on level ground to cover a 5-foot-square area within 5 feet of yourself. If lit, the oil burns until the end of the turn 2 rounds from when the oil was lit (or 12 seconds) and deals 5 Fire damage to any creature that enters the area or ends its turn there. A creature can take this damage only once per turn. Fuel. Oil serves as fuel for Lamps and Lanterns. Once lit, a flask of Oil burns for 6 hours in a Lamp or Lantern. That duration doesn’t need to be consecutive; you can extinguish the burning Oil (as a Utilize action) and rekindle it again until it has burned for a total of 6 hours.
A14: Parchment | B14: Adventuring Gear | C14: Udstyr | D14: Player's Handbook | E14: =IF(G14<Oversigt!$I$8,Oversigt!$H$8,IF(G14<Oversigt!$I$9,Oversigt!$H$9,IF(G14<Oversigt!$I$10,Oversigt!$H$10,IF(G14<Oversigt!$I$11,Oversigt!$H$11,IF(G14<Oversigt!$I$12,Oversigt!$H$12,Oversigt!$H$13))))) -> Common | F14: 1 SP | G14: 0.1 | Q14: Communication, Social, Utility, Consumable | S14: One sheet of Parchment can hold about 250 handwritten words.
A15: String | B15: Adventuring Gear | C15: Udstyr | D15: Player's Handbook | E15: =IF(G15<Oversigt!$I$8,Oversigt!$H$8,IF(G15<Oversigt!$I$9,Oversigt!$H$9,IF(G15<Oversigt!$I$10,Oversigt!$H$10,IF(G15<Oversigt!$I$11,Oversigt!$H$11,IF(G15<Oversigt!$I$12,Oversigt!$H$12,Oversigt!$H$13))))) -> Common | F15: 1 SP | G15: 0.1 | Q15: Utility | S15: String is 10 feet long. You can tie a knot in it as a Utilize action.
A16: Paper | B16: Adventuring Gear | C16: Udstyr | D16: Player's Handbook | E16: =IF(G16<Oversigt!$I$8,Oversigt!$H$8,IF(G16<Oversigt!$I$9,Oversigt!$H$9,IF(G16<Oversigt!$I$10,Oversigt!$H$10,IF(G16<Oversigt!$I$11,Oversigt!$H$11,IF(G16<Oversigt!$I$12,Oversigt!$H$12,Oversigt!$H$13))))) -> Common | F16: 2 SP | G16: 0.2 | Q16: Communication, Social, Utility, Consumable | S16: One sheet of Paper can hold about 250 handwritten words.
A17: Waterskin | B17: Adventuring Gear | C17: Udstyr | D17: Player's Handbook | E17: =IF(G17<Oversigt!$I$8,Oversigt!$H$8,IF(G17<Oversigt!$I$9,Oversigt!$H$9,IF(G17<Oversigt!$I$10,Oversigt!$H$10,IF(G17<Oversigt!$I$11,Oversigt!$H$11,IF(G17<Oversigt!$I$12,Oversigt!$H$12,Oversigt!$H$13))))) -> Common | F17: 2 SP | G17: 0.2 | H17: 5 lbs | I17: 5 | Q17: Container | S17: A Waterskin holds up to 4 pints. If you don’t drink sufficient water, you risk dehydration.
A18: Lamp | B18: Adventuring Gear | C18: Udstyr | D18: Player's Handbook | E18: =IF(G18<Oversigt!$I$8,Oversigt!$H$8,IF(G18<Oversigt!$I$9,Oversigt!$H$9,IF(G18<Oversigt!$I$10,Oversigt!$H$10,IF(G18<Oversigt!$I$11,Oversigt!$H$11,IF(G18<Oversigt!$I$12,Oversigt!$H$12,Oversigt!$H$13))))) -> Common | F18: 5 SP | G18: 0.5 | H18: 1 lb | I18: 1 | Q18: Utility, Exploration | S18: A Lamp burns Oil as fuel to cast Bright Light in a 15-foot radius and Dim Light for an additional 30 feet.
A19: Pouch | B19: Adventuring Gear | C19: Udstyr | D19: Player's Handbook | E19: =IF(G19<Oversigt!$I$8,Oversigt!$H$8,IF(G19<Oversigt!$I$9,Oversigt!$H$9,IF(G19<Oversigt!$I$10,Oversigt!$H$10,IF(G19<Oversigt!$I$11,Oversigt!$H$11,IF(G19<Oversigt!$I$12,Oversigt!$H$12,Oversigt!$H$13))))) -> Common | F19: 5 SP | G19: 0.5 | H19: 1 lb | I19: 1 | Q19: Container | S19: A Pouch holds up to 6 pounds within one-fifth of a cubic foot.
A20: Rations | B20: Adventuring Gear | C20: Udstyr | D20: Player's Handbook | E20: =IF(G20<Oversigt!$I$8,Oversigt!$H$8,IF(G20<Oversigt!$I$9,Oversigt!$H$9,IF(G20<Oversigt!$I$10,Oversigt!$H$10,IF(G20<Oversigt!$I$11,Oversigt!$H$11,IF(G20<Oversigt!$I$12,Oversigt!$H$12,Oversigt!$H$13))))) -> Common | F20: 5 SP | G20: 0.5 | H20: 2 lbs | I20: 2 | Q20: Social, Utility, Consumable | S20: Rations consist of travel-ready food, including jerky, dried fruit, hardtack, and nuts. See “Malnutrition” for the risks of not eating.
A21: Tinderbox | B21: Adventuring Gear | C21: Udstyr | D21: Player's Handbook | E21: =IF(G21<Oversigt!$I$8,Oversigt!$H$8,IF(G21<Oversigt!$I$9,Oversigt!$H$9,IF(G21<Oversigt!$I$10,Oversigt!$H$10,IF(G21<Oversigt!$I$11,Oversigt!$H$11,IF(G21<Oversigt!$I$12,Oversigt!$H$12,Oversigt!$H$13))))) -> Common | F21: 5 SP | G21: 0.5 | H21: 1 lb | I21: 1 | Q21: Utility, Exploration | S21: A Tinderbox is a small container holding flint, fire steel, and tinder (usually dry cloth soaked in light oil) used to kindle a fire. Using it to light a Candle, Lamp, Lantern, or Torch—or anything else with exposed fuel—takes a Bonus Action. Lighting any other fire takes 1 minute.
A22: Caltrops | B22: Adventuring Gear | C22: Udstyr | D22: Player's Handbook | E22: =IF(G22<Oversigt!$I$8,Oversigt!$H$8,IF(G22<Oversigt!$I$9,Oversigt!$H$9,IF(G22<Oversigt!$I$10,Oversigt!$H$10,IF(G22<Oversigt!$I$11,Oversigt!$H$11,IF(G22<Oversigt!$I$12,Oversigt!$H$12,Oversigt!$H$13))))) -> Common | F22: 1 GP | G22: 1 | H22: 2 lbs | I22: 2 | Q22: Damage, Movement, Combat | S22: As a Utilize action, you can spread Caltrops from their bag to cover a 5-foot-square area within 5 feet of yourself. A creature that enters this area for the first time on a turn must succeed on a DC 15 Dexterity saving throw or take 1 Piercing damage and have its Speed reduced to 0 until the start of its next turn. It takes 10 minutes to recover the Caltrops.
A23: Crossbow Bolt Case | B23: Adventuring Gear | C23: Udstyr | D23: Player's Handbook | E23: =IF(G23<Oversigt!$I$8,Oversigt!$H$8,IF(G23<Oversigt!$I$9,Oversigt!$H$9,IF(G23<Oversigt!$I$10,Oversigt!$H$10,IF(G23<Oversigt!$I$11,Oversigt!$H$11,IF(G23<Oversigt!$I$12,Oversigt!$H$12,Oversigt!$H$13))))) -> Common | F23: 1 GP | G23: 1 | H23: 1 lb | I23: 1 | Q23: Container | S23: A Crossbow Bolt Case holds up to 20 Bolts.
A24: Iron Spikes | B24: Adventuring Gear | C24: Udstyr | D24: Player's Handbook | E24: =IF(G24<Oversigt!$I$8,Oversigt!$H$8,IF(G24<Oversigt!$I$9,Oversigt!$H$9,IF(G24<Oversigt!$I$10,Oversigt!$H$10,IF(G24<Oversigt!$I$11,Oversigt!$H$11,IF(G24<Oversigt!$I$12,Oversigt!$H$12,Oversigt!$H$13))))) -> Common | F24: 1 GP | G24: 1 | H24: 5 lbs | I24: 5 | Q24: Utility | S24: Iron Spikes come in bundles of ten. As a Utilize action, you can use a blunt object, such as a Light Hammer, to hammer a spike into wood, earth, or a similar material. You can do so to jam a door shut or to then tie a Rope or Chain to the Spike.
A25: Map | B25: Adventuring Gear | C25: Udstyr | D25: Player's Handbook | E25: =IF(G25<Oversigt!$I$8,Oversigt!$H$8,IF(G25<Oversigt!$I$9,Oversigt!$H$9,IF(G25<Oversigt!$I$10,Oversigt!$H$10,IF(G25<Oversigt!$I$11,Oversigt!$H$11,IF(G25<Oversigt!$I$12,Oversigt!$H$12,Oversigt!$H$13))))) -> Common | F25: 1 GP | G25: 1 | S25: If you consult an accurate Map, you gain a +5 bonus to Wisdom (Survival) checks you make to find your way in the place represented on it.
A26: Map or Scroll Case | B26: Adventuring Gear | C26: Udstyr | D26: Player's Handbook | E26: =IF(G26<Oversigt!$I$8,Oversigt!$H$8,IF(G26<Oversigt!$I$9,Oversigt!$H$9,IF(G26<Oversigt!$I$10,Oversigt!$H$10,IF(G26<Oversigt!$I$11,Oversigt!$H$11,IF(G26<Oversigt!$I$12,Oversigt!$H$12,Oversigt!$H$13))))) -> Common | F26: 1 GP | G26: 1 | H26: 1 lb | I26: 1 | Q26: Container | S26: A Map or Scroll Case holds up to 10 sheets of paper or 5 sheets of parchment.
A27: Net | B27: Adventuring Gear | C27: Udstyr | D27: Player's Handbook | E27: =IF(G27<Oversigt!$I$8,Oversigt!$H$8,IF(G27<Oversigt!$I$9,Oversigt!$H$9,IF(G27<Oversigt!$I$10,Oversigt!$H$10,IF(G27<Oversigt!$I$11,Oversigt!$H$11,IF(G27<Oversigt!$I$12,Oversigt!$H$12,Oversigt!$H$13))))) -> Common | F27: 1 GP | G27: 1 | H27: 3 lbs | I27: 3 | S27: When you take the Attack action, you can replace one of your attacks with throwing a Net. Target a creature you can see within 15 feet of yourself. The target must succeed on a Dexterity saving throw (DC 8 plus your Dexterity modifier and Proficiency Bonus) or have the Restrained condition until it escapes. The target succeeds automatically if it is Huge or larger. To escape, the target or a creature within 5 feet of it must take an action to make a DC 10 Strength (Athletics) check, freeing the Restrained creature on a success. Destroying the Net (AC 10; 5 HP; Immunity to Bludgeoning, Poison, and Psychic damage) also frees the target, ending the effect.
A28: Quiver | B28: Adventuring Gear | C28: Udstyr | D28: Player's Handbook | E28: =IF(G28<Oversigt!$I$8,Oversigt!$H$8,IF(G28<Oversigt!$I$9,Oversigt!$H$9,IF(G28<Oversigt!$I$10,Oversigt!$H$10,IF(G28<Oversigt!$I$11,Oversigt!$H$11,IF(G28<Oversigt!$I$12,Oversigt!$H$12,Oversigt!$H$13))))) -> Common | F28: 1 GP | G28: 1 | H28: 1 lb | I28: 1 | Q28: Container | S28: A Quiver holds up to 20 Arrows.
A29: Robe | B29: Adventuring Gear | C29: Udstyr | D29: Player's Handbook | E29: =IF(G29<Oversigt!$I$8,Oversigt!$H$8,IF(G29<Oversigt!$I$9,Oversigt!$H$9,IF(G29<Oversigt!$I$10,Oversigt!$H$10,IF(G29<Oversigt!$I$11,Oversigt!$H$11,IF(G29<Oversigt!$I$12,Oversigt!$H$12,Oversigt!$H$13))))) -> Common | F29: 1 GP | G29: 1 | H29: 4 lbs | I29: 4 | S29: A Robe has vocational or ceremonial significance. Some events and locations admit only people wearing a Robe bearing certain colors or symbols.
A30: Rope | B30: Adventuring Gear | C30: Udstyr | D30: Player's Handbook | E30: =IF(G30<Oversigt!$I$8,Oversigt!$H$8,IF(G30<Oversigt!$I$9,Oversigt!$H$9,IF(G30<Oversigt!$I$10,Oversigt!$H$10,IF(G30<Oversigt!$I$11,Oversigt!$H$11,IF(G30<Oversigt!$I$12,Oversigt!$H$12,Oversigt!$H$13))))) -> Common | F30: 1 GP | G30: 1 | H30: 5 lbs | I30: 5 | S30: As a Utilize action, you can tie a knot with Rope if you succeed on a DC 10 Dexterity (Sleight of Hand) check. The Rope can be burst with a successful DC 20 Strength (Athletics) check. You can bind an unwilling creature with the Rope only if the creature has the Grappled, Incapacitated, or Restrained condition. If the creature’s legs are bound, the creature has the Restrained condition until it escapes. Escaping the Rope requires the creature to make a successful DC 15 Dexterity (Acrobatics) check as an action.
A31: Vial | B31: Adventuring Gear | C31: Udstyr | D31: Player's Handbook | E31: =IF(G31<Oversigt!$I$8,Oversigt!$H$8,IF(G31<Oversigt!$I$9,Oversigt!$H$9,IF(G31<Oversigt!$I$10,Oversigt!$H$10,IF(G31<Oversigt!$I$11,Oversigt!$H$11,IF(G31<Oversigt!$I$12,Oversigt!$H$12,Oversigt!$H$13))))) -> Common | F31: 1 GP | G31: 1 | Q31: Container | S31: A Vial holds up to 4 ounces.
A32: Crowbar | B32: Adventuring Gear | C32: Udstyr | D32: Player's Handbook | E32: =IF(G32<Oversigt!$I$8,Oversigt!$H$8,IF(G32<Oversigt!$I$9,Oversigt!$H$9,IF(G32<Oversigt!$I$10,Oversigt!$H$10,IF(G32<Oversigt!$I$11,Oversigt!$H$11,IF(G32<Oversigt!$I$12,Oversigt!$H$12,Oversigt!$H$13))))) -> Uncommon | F32: 2 GP | G32: 2 | H32: 5 lbs | I32: 5 | Q32: Utility, Exploration | S32: Using a Crowbar gives you Advantage on Strength checks where the Crowbar’s leverage can be applied.
A33: Glass Bottle | B33: Adventuring Gear | C33: Udstyr | D33: Player's Handbook | E33: =IF(G33<Oversigt!$I$8,Oversigt!$H$8,IF(G33<Oversigt!$I$9,Oversigt!$H$9,IF(G33<Oversigt!$I$10,Oversigt!$H$10,IF(G33<Oversigt!$I$11,Oversigt!$H$11,IF(G33<Oversigt!$I$12,Oversigt!$H$12,Oversigt!$H$13))))) -> Uncommon | F33: 2 GP | G33: 2 | H33: 2 lbs | I33: 2 | Q33: Container | S33: A Glass Bottle holds up to 1½ pints.
A34: Grappling Hook | B34: Adventuring Gear | C34: Udstyr | D34: Player's Handbook | E34: =IF(G34<Oversigt!$I$8,Oversigt!$H$8,IF(G34<Oversigt!$I$9,Oversigt!$H$9,IF(G34<Oversigt!$I$10,Oversigt!$H$10,IF(G34<Oversigt!$I$11,Oversigt!$H$11,IF(G34<Oversigt!$I$12,Oversigt!$H$12,Oversigt!$H$13))))) -> Uncommon | F34: 2 GP | G34: 2 | H34: 4 lbs | I34: 4 | Q34: Utility, Exploration | S34: As a Utilize action, you can throw the Grappling Hook at a railing, a ledge, or another catch within 50 feet of yourself, and the hook catches on if you succeed on a DC 13 Dexterity (Acrobatics) check. If you tied a Rope to the hook, you can then climb it.
A35: Iron Pot | B35: Adventuring Gear | C35: Udstyr | D35: Player's Handbook | E35: =IF(G35<Oversigt!$I$8,Oversigt!$H$8,IF(G35<Oversigt!$I$9,Oversigt!$H$9,IF(G35<Oversigt!$I$10,Oversigt!$H$10,IF(G35<Oversigt!$I$11,Oversigt!$H$11,IF(G35<Oversigt!$I$12,Oversigt!$H$12,Oversigt!$H$13))))) -> Uncommon | F35: 2 GP | G35: 2 | H35: 10 lbs | I35: 10 | Q35: Container | S35: An Iron Pot holds up to 1 gallon.
A36: Manacles | B36: Adventuring Gear | C36: Udstyr | D36: Player's Handbook | E36: =IF(G36<Oversigt!$I$8,Oversigt!$H$8,IF(G36<Oversigt!$I$9,Oversigt!$H$9,IF(G36<Oversigt!$I$10,Oversigt!$H$10,IF(G36<Oversigt!$I$11,Oversigt!$H$11,IF(G36<Oversigt!$I$12,Oversigt!$H$12,Oversigt!$H$13))))) -> Uncommon | F36: 2 GP | G36: 2 | H36: 6 lbs | I36: 6 | Q36: Control, Utility | S36: As a Utilize action, you can use Manacles to bind an unwilling Small or Medium creature within 5 feet of yourself that has the Grappled, Incapacitated, or Restrained condition if you succeed on a DC 13 Dexterity (Sleight of Hand) check. While bound, a creature has Disadvantage on attack rolls, and the creature is Restrained if the Manacles are attached to a chain or hook that is fixed in place. Escaping the Manacles requires a successful DC 20 Dexterity (Sleight of Hand) check as an action. Bursting them requires a successful DC 25 Strength (Athletics) check as an action. Each set of Manacles comes with a key. Without the key, a creature can use Thieves’ Tools to pick the Manacles’ lock with a successful DC 15 Dexterity (Sleight of Hand) check.
A37: Shovel | B37: Adventuring Gear | C37: Udstyr | D37: Player's Handbook | E37: =IF(G37<Oversigt!$I$8,Oversigt!$H$8,IF(G37<Oversigt!$I$9,Oversigt!$H$9,IF(G37<Oversigt!$I$10,Oversigt!$H$10,IF(G37<Oversigt!$I$11,Oversigt!$H$11,IF(G37<Oversigt!$I$12,Oversigt!$H$12,Oversigt!$H$13))))) -> Uncommon | F37: 2 GP | G37: 2 | H37: 5 lbs | I37: 5 | Q37: Utility | S37: Working for 1 hour, you can use a Shovel to dig a hole that is 5 feet on each side in soil or similar material.
A38: Tent | B38: Adventuring Gear | C38: Udstyr | D38: Player's Handbook | E38: =IF(G38<Oversigt!$I$8,Oversigt!$H$8,IF(G38<Oversigt!$I$9,Oversigt!$H$9,IF(G38<Oversigt!$I$10,Oversigt!$H$10,IF(G38<Oversigt!$I$11,Oversigt!$H$11,IF(G38<Oversigt!$I$12,Oversigt!$H$12,Oversigt!$H$13))))) -> Uncommon | F38: 2 GP | G38: 2 | H38: 20 lbs | I38: 20 | Q38: Social, Utility, Exploration | S38: A Tent sleeps up to two Small or Medium creatures.
A39: Traveler's Clothes | B39: Adventuring Gear | C39: Udstyr | D39: Player's Handbook | E39: =IF(G39<Oversigt!$I$8,Oversigt!$H$8,IF(G39<Oversigt!$I$9,Oversigt!$H$9,IF(G39<Oversigt!$I$10,Oversigt!$H$10,IF(G39<Oversigt!$I$11,Oversigt!$H$11,IF(G39<Oversigt!$I$12,Oversigt!$H$12,Oversigt!$H$13))))) -> Uncommon | F39: 2 GP | G39: 2 | H39: 4 lbs | I39: 4 | Q39: Social, Outerwear | S39: Traveler’s Clothes are resilient garments designed for travel in various environments.
A40: Portable Ram | B40: Adventuring Gear | C40: Udstyr | D40: Player's Handbook | E40: =IF(G40<Oversigt!$I$8,Oversigt!$H$8,IF(G40<Oversigt!$I$9,Oversigt!$H$9,IF(G40<Oversigt!$I$10,Oversigt!$H$10,IF(G40<Oversigt!$I$11,Oversigt!$H$11,IF(G40<Oversigt!$I$12,Oversigt!$H$12,Oversigt!$H$13))))) -> Uncommon | F40: 4 GP | G40: 4 | H40: 35 lbs | I40: 35 | Q40: Utility, Exploration | S40: You can use a Portable Ram to break down doors. When doing so, you gain a +4 bonus to the Strength check. One other character can help you use the ram, giving you Advantage on this check.
...

Sheet Ark1

Sheet Våben
A1: Navn | B1: Kategori | C1: Skade | D1: Skadetype | E1: Egenskaber | F1: Mastery | G1: Pris | H1: Pris (GP) | I1: Vægt | J1: Vægt (lbs) | K1: Kilde | L1: Beskrivelse
A2: Dart | B2: Simple Ranged Weapon | C2: 1d4 | D2: Piercing | E2: Finesse, Thrown (range 20/60), Vex | F2: Vex | G2: 5 CP | H2: 0.05 | I2: 1/4 lb | J2: 0.25 | K2: D&D Beyond Basic Rules | L2: Proficiency with a Dart allows you to add your proficiency bonus to the attack roll for any attack you make with it. This weapon has the following mastery property. To use this property, you must have a feature that lets you use it. Vex. If you hit a creature with this weapon and deal damage to the creature, you have Advantage on your next attack roll against that creature before the end of your next turn.
A3: Club | B3: Simple Melee Weapon | C3: 1d4 | D3: Bludgeoning | E3: Light, Slow | F3: Slow | G3: 1 SP | H3: 0.1 | I3: 2 lbs | J3: 2 | K3: D&D Beyond Basic Rules | L3: Proficiency with a Club allows you to add your proficiency bonus to the attack roll for any attack you make with it. This weapon has the following mastery property. To use this property, you must have a feature that lets you use it. Slow. If you hit a creature with this weapon and deal damage to it, you can reduce its Speed by 10 feet until the start of your next turn. If the creature is hit more than once by weapons that have this property, the Speed reduction doesn’t exceed 10 feet.
A4: Sling | B4: Simple Ranged Weapon | C4: 1d4 | D4: Bludgeoning | E4: Ammunition, (Range 30/120), Slow | F4: Slow | G4: 1 SP | H4: 0.1 | K4: D&D Beyond Basic Rules | L4: Proficiency with a Sling allows you to add your proficiency bonus to the attack roll for any attack you make with it. This weapon has the following mastery property. To use this property, you must have a feature that lets you use it. Slow. If you hit a creature with this weapon and deal damage to it, you can reduce its Speed by 10 feet until the start of your next turn. If the creature is hit more than once by weapons that have this property, the Speed reduction doesn’t exceed 10 feet.
A5: Greatclub | B5: Simple Melee Weapon | C5: 1d8 | D5: Bludgeoning | E5: Two-Handed, Push | F5: Push | G5: 2 SP | H5: 0.2 | I5: 10 lbs | J5: 10 | K5: D&D Beyond Basic Rules | L5: Proficiency with a Greatclub allows you to add your proficiency bonus to the attack roll for any attack you make with it. This weapon has the following mastery property. To use this property, you must have a feature that lets you use it. Push. If you hit a creature with this weapon, you can push the creature up to 10 feet straight away from yourself if it is Large or smaller.
A6: Quarterstaff | B6: Simple Melee Weapon | C6: 1d6 | D6: Bludgeoning | E6: Versatile (1d8), Topple | F6: Topple | G6: 2 SP | H6: 0.2 | I6: 4 lbs | J6: 4 | K6: D&D Beyond Basic Rules | L6: Proficiency with a Quarterstaff allows you to add your proficiency bonus to the attack roll for any attack you make with it. This weapon has the following mastery property. To use this property, you must have a feature that lets you use it. Topple. If you hit a creature with this weapon, you can force the creature to make a Constitution saving throw (DC 8 plus the ability modifier used to make the attack roll and your Proficiency Bonus). On a failed save, the creature has the Prone condition.
A7: Javelin | B7: Simple Melee Weapon | C7: 1d6 | D7: Piercing | E7: Thrown (range 30/120), Slow | F7: Slow | G7: 5 SP | H7: 0.5 | I7: 2 lbs | J7: 2 | K7: D&D Beyond Basic Rules | L7: Proficiency with a Javelin allows you to add your proficiency bonus to the attack roll for any attack you make with it. This weapon has the following mastery property. To use this property, you must have a feature that lets you use it. Slow. If you hit a creature with this weapon and deal damage to it, you can reduce its Speed by 10 feet until the start of your next turn. If the creature is hit more than once by weapons that have this property, the Speed reduction doesn’t exceed 10 feet.
A8: Sickle | B8: Simple Melee Weapon | C8: 1d4 | D8: Slashing | E8: Light, Nick | F8: Nick | G8: 1 GP | H8: 1 | I8: 2 lbs | J8: 2 | K8: D&D Beyond Basic Rules | L8: Proficiency with a Sickle allows you to add your proficiency bonus to the attack roll for any attack you make with it. This weapon has the following mastery property. To use this property, you must have a feature that lets you use it. Nick. When you make the extra attack of the Light property, you can make it as part of the Attack action instead of as a Bonus Action. You can make this extra attack only once per turn.
A9: Spear | B9: Simple Melee Weapon | C9: 1d6 | D9: Piercing | E9: Thrown (range 20/60), Versatile (1d8), Sap | F9: Sap | G9: 1 GP | H9: 1 | I9: 3 lbs | J9: 3 | K9: D&D Beyond Basic Rules | L9: Proficiency with a Spear allows you to add your proficiency bonus to the attack roll for any attack you make with it. This weapon has the following mastery property. To use this property, you must have a feature that lets you use it. Sap. If you hit a creature with this weapon, that creature has Disadvantage on its next attack roll before the start of your next turn.
A10: Dagger | B10: Simple Melee Weapon | C10: 1d4 | D10: Piercing | E10: Finesse, Light, Thrown (range 20/60), Nick | F10: Nick | G10: 2 GP | H10: 2 | I10: 1 lb | J10: 1 | K10: D&D Beyond Basic Rules | L10: Proficiency with a Dagger allows you to add your proficiency bonus to the attack roll for any attack you make with it. This weapon has the following mastery property. To use this property, you must have a feature that lets you use it. Nick. When you make the extra attack of the Light property, you can make it as part of the Attack action instead of as a Bonus Action. You can make this extra attack only once per turn.
A11: Light Hammer | B11: Simple Melee Weapon | C11: 1d4 | D11: Bludgeoning | E11: Light, Thrown (range 20/60), Nick | F11: Nick | G11: 2 GP | H11: 2 | I11: 2 lbs | J11: 2 | K11: D&D Beyond Basic Rules | L11: Proficiency with a Light Hammer allows you to add your proficiency bonus to the attack roll for any attack you make with it. This weapon has the following mastery property. To use this property, you must have a feature that lets you use it. Nick. When you make the extra attack of the Light property, you can make it as part of the Attack action instead of as a Bonus Action. You can make this extra attack only once per turn.
A12: Whip | B12: Martial Melee Weapon | C12: 1d4 | D12: Slashing | E12: Finesse, Reach, Slow | F12: Slow | G12: 2 GP | H12: 2 | I12: 3 lbs | J12: 3 | K12: D&D Beyond Basic Rules | L12: Proficiency with a Whip allows you to add your proficiency bonus to the attack roll for any attack you make with it. This weapon has the following mastery property. To use this property, you must have a feature that lets you use it. Slow. If you hit a creature with this weapon and deal damage to it, you can reduce its Speed by 10 feet until the start of your next turn. If the creature is hit more than once by weapons that have this property, the Speed reduction doesn’t exceed 10 feet.
A13: Handaxe | B13: Simple Melee Weapon | C13: 1d6 | D13: Slashing | E13: Light, Thrown (range 20/60), Vex | F13: Vex | G13: 5 GP | H13: 5 | I13: 2 lbs | J13: 2 | K13: D&D Beyond Basic Rules | L13: Proficiency with a Handaxe allows you to add your proficiency bonus to the attack roll for any attack you make with it. This weapon has the following mastery property. To use this property, you must have a feature that lets you use it. Vex. If you hit a creature with this weapon and deal damage to the creature, you have Advantage on your next attack roll against that creature before the end of your next turn.
A14: Mace | B14: Simple Melee Weapon | C14: 1d6 | D14: Bludgeoning | E14: Sap | F14: Sap | G14: 5 GP | H14: 5 | I14: 4 lbs | J14: 4 | K14: D&D Beyond Basic Rules | L14: Proficiency with a Mace allows you to add your proficiency bonus to the attack roll for any attack you make with it. This weapon has the following mastery property. To use this property, you must have a feature that lets you use it. Sap. If you hit a creature with this weapon, that creature has Disadvantage on its next attack roll before the start of your next turn.
A15: Pike | B15: Martial Melee Weapon | C15: 1d10 | D15: Piercing | E15: Heavy, Reach, Two-Handed, Push | F15: Push | G15: 5 GP | H15: 5 | I15: 18 lbs | J15: 18 | K15: D&D Beyond Basic Rules | L15: Proficiency with a Pike allows you to add your proficiency bonus to the attack roll for any attack you make with it. This weapon has the following mastery property. To use this property, you must have a feature that lets you use it. Push. If you hit a creature with this weapon, you can push the creature up to 10 feet straight away from yourself if it is Large or smaller.
A16: Trident | B16: Martial Melee Weapon | C16: 1d8 | D16: Piercing | E16: Thrown (range 20/60), Versatile (1d10), Topple | F16: Topple | G16: 5 GP | H16: 5 | I16: 4 lbs | J16: 4 | K16: D&D Beyond Basic Rules | L16: Proficiency with a Trident allows you to add your proficiency bonus to the attack roll for any attack you make with it. This weapon has the following mastery property. To use this property, you must have a feature that lets you use it. Topple. If you hit a creature with this weapon, you can force the creature to make a Constitution saving throw (DC 8 plus the ability modifier used to make the attack roll and your Proficiency Bonus). On a failed save, the creature has the Prone condition.
... A37: Musket | B37: Martial Ranged Weapon | C37: 1d12 | D37: Piercing | E37: Ammunition (Firearms), (Range 40/120), Loading, Two-Handed, Slow | F37: Slow | G37: 500 GP | H37: 500 | I37: 10 lbs | J37: 10 | K37: Player's Handbook | L37: Proficiency with a Musket allows you to add your proficiency bonus to the attack roll for any attack you make with it. This weapon has the following mastery property. To use this property, you must have a feature that lets you use it. Slow. If you hit a creature with this weapon and deal damage to it, you can reduce its Speed by 10 feet until the start of your next turn. If the creature is hit more than once by weapons that have this property, the Speed reduction doesn’t exceed 10 feet.
A38: Laser Pistol | B38: Firearms Ranged Weapon | C38: 3d6 | D38: Radiant | E38: Ammunition (Firearms), (Range 40/120), Reload, Vex | F38: Vex | I38: 2 lbs | J38: 2 | K38: Dungeon Master's Guide | L38: It’s up to you to decide whether a character has proficiency with a firearm. Characters in most D&D worlds wouldn’t have such proficiency. During their downtime, characters can use the training rules in the Player’s Handbook to acquire proficiency, assuming that they have enough ammunition to keep the weapons working while mastering their use. This weapon has the following mastery property. To use this property, you must have a feature that lets you use it. Vex. If you hit a creature with this weapon and deal damage to the creature, you have Advantage on your next attack roll against that creature before the end of your next turn. Notes: Reload (50 shots)
A39: Laser Rifle | B39: Firearms Ranged Weapon | C39: 3d8 | D39: Radiant | E39: Ammunition (Firearms), (Range 100/300), Reload, Two-Handed, Slow | F39: Slow | I39: 7 lbs | J39: 7 | K39: Dungeon Master's Guide | L39: It’s up to you to decide whether a character has proficiency with a firearm. Characters in most D&D worlds wouldn’t have such proficiency. During their downtime, characters can use the training rules in the Player’s Handbook to acquire proficiency, assuming that they have enough ammunition to keep the weapons working while mastering their use. This weapon has the following mastery property. To use this property, you must have a feature that lets you use it. Slow. If you hit a creature with this weapon and deal damage to it, you can reduce its Speed by 10 feet until the start of your next turn. If the creature is hit more than once by weapons that have this property, the Speed reduction doesn’t exceed 10 feet. Notes: Reload (30 shots)
A40: Revolver | B40: Firearms Ranged Weapon | C40: 2d8 | D40: Piercing | E40: Ammunition (Firearms), (Range 40/120), Reload, Sap | F40: Sap | I40: 3 lbs | J40: 3 | K40: Dungeon Master's Guide | L40: It’s up to you to decide whether a character has proficiency with a firearm. Characters in most D&D worlds wouldn’t have such proficiency. During their downtime, characters can use the training rules in the Player’s Handbook to acquire proficiency, assuming that they have enough ammunition to keep the weapons working while mastering their use. This weapon has the following mastery property. To use this property, you must have a feature that lets you use it. Sap. If you hit a creature with this weapon, that creature has Disadvantage on its next attack roll before the start of your next turn. Notes: Reload (6 shots)
A41: Rifle, Automatic | B41: Firearms Ranged Weapon | C41: 2d8 | D41: Piercing | E41: Ammunition (Firearms), (Range 80/240), Reload, Two-Handed, Burst Fire, Slow | F41: Slow | I41: 8 lbs | J41: 8 | K41: Dungeon Master's Guide | L41: It’s up to you to decide whether a character has proficiency with a firearm. Characters in most D&D worlds wouldn’t have such proficiency. During their downtime, characters can use the training rules in the Player’s Handbook to acquire proficiency, assuming that they have enough ammunition to keep the weapons working while mastering their use. This weapon has the following mastery property. To use this property, you must have a feature that lets you use it. Slow. If you hit a creature with this weapon and deal damage to it, you can reduce its Speed by 10 feet until the start of your next turn. If the creature is hit more than once by weapons that have this property, the Speed reduction doesn’t exceed 10 feet. Notes: Reload (30 shots)
A42: Rifle, Hunting | B42: Firearms Ranged Weapon | C42: 2d10 | D42: Piercing | E42: Ammunition (Firearms), (Range 80/240), Reload, Two-Handed, Slow | F42: Slow | I42: 8 lbs | J42: 8 | K42: Dungeon Master's Guide | L42: It’s up to you to decide whether a character has proficiency with a firearm. Characters in most D&D worlds wouldn’t have such proficiency. During their downtime, characters can use the training rules in the Player’s Handbook to acquire proficiency, assuming that they have enough ammunition to keep the weapons working while mastering their use. This weapon has the following mastery property. To use this property, you must have a feature that lets you use it. Slow. If you hit a creature with this weapon and deal damage to it, you can reduce its Speed by 10 feet until the start of your next turn. If the creature is hit more than once by weapons that have this property, the Speed reduction doesn’t exceed 10 feet. Notes: Reload (5 shots)
A43: Semiautomatic Pistol | B43: Firearms Ranged Weapon | C43: 2d6 | D43: Piercing | E43: Ammunition (Firearms), (Range 50/150), Reload, Vex | F43: Vex | I43: 3 lbs | J43: 3 | K43: Dungeon Master's Guide | L43: It’s up to you to decide whether a character has proficiency with a firearm. Characters in most D&D worlds wouldn’t have such proficiency. During their downtime, characters can use the training rules in the Player’s Handbook to acquire proficiency, assuming that they have enough ammunition to keep the weapons working while mastering their use. This weapon has the following mastery property. To use this property, you must have a feature that lets you use it. Vex. If you hit a creature with this weapon and deal damage to the creature, you have Advantage on your next attack roll against that creature before the end of your next turn.
A44: Shotgun | B44: Firearms Ranged Weapon | C44: 2d8 | D44: Piercing | E44: Ammunition (Firearms), (Range 30/90), Reload, Two-Handed, Push | F44: Push | I44: 7 lbs | J44: 7 | K44: Dungeon Master's Guide | L44: It’s up to you to decide whether a character has proficiency with a firearm. Characters in most D&D worlds wouldn’t have such proficiency. During their downtime, characters can use the training rules in the Player’s Handbook to acquire proficiency, assuming that they have enough ammunition to keep the weapons working while mastering their use. This weapon has the following mastery property. To use this property, you must have a feature that lets you use it. Push. If you hit a creature with this weapon, you can push the creature up to 10 feet straight away from yourself if it is Large or smaller. Notes: Reload (2 shots)

Sheet Rustning
A1: Navn | B1: Kategori | C1: AC | D1: Styrkekrav | E1: Stealth | F1: Pris | G1: Pris (GP) | H1: Vægt | I1: Vægt (lbs) | J1: Kilde | K1: Beskrivelse
A2: Breastplate | B2: Medium Armor | C2: 14 + Dex modifier (max 2) | F2: 400 GP | G2: 400 | H2: 20 lbs | I2: 20 | J2: D&D Beyond Basic Rules | K2: This armor consists of a fitted metal chest piece worn with supple leather. Although it leaves the legs and arms relatively unprotected, this armor provides good protection for the wearer's vital organs while leaving the wearer relatively unencumbered.
A3: Chain Mail | B3: Heavy Armor | C3: 16 | D3: 13 | E3: Disadvantage | F3: 75 GP | G3: 75 | H3: 55 lbs | I3: 55 | J3: D&D Beyond Basic Rules | K3: Made of interlocking metal rings, chain mail includes a layer of quilted fabric worn underneath the mail to prevent chafing and to cushion the impact of blows. The suit includes gauntlets.
A4: Chain Shirt | B4: Medium Armor | C4: 13 + Dex modifier (max 2) | F4: 50 GP | G4: 50 | H4: 20 lbs | I4: 20 | J4: D&D Beyond Basic Rules | K4: Made of interlocking metal rings, a chain shirt is worn between layers of clothing or leather. This armor offers modest protection to the wearer's upper body and allows the sound of the rings rubbing against one another to be muffled by outer layers.
A5: Half Plate | B5: Medium Armor | C5: 15 + Dex modifier (max 2) | E5: Disadvantage | F5: 750 GP | G5: 750 | H5: 40 lbs | I5: 40 | J5: D&D Beyond Basic Rules | K5: Half plate consists of shaped metal plates that cover most of the wearer's body. It does not include leg protection beyond simple greaves that are attached with leather straps.
A6: Hide | B6: Medium Armor | C6: 12 + Dex modifier (max 2) | F6: 10 GP | G6: 10 | H6: 12 lbs | I6: 12 | J6: D&D Beyond Basic Rules | K6: This crude armor consists of thick furs and pelts.
A7: Leather | B7: Light Armor | C7: 11 + Dex modifier | F7: 10 GP | G7: 10 | H7: 10 lbs | I7: 10 | J7: D&D Beyond Basic Rules | K7: The breastplate and shoulder protectors of this armor are made of leather that has been stiffened by being boiled in oil. The rest of the armor is made of softer and more flexible materials.
A8: Padded | B8: Light Armor | C8: 11 + Dex modifier | E8: Disadvantage | F8: 5 GP | G8: 5 | H8: 8 lbs | I8: 8 | J8: D&D Beyond Basic Rules | K8: Padded armor consists of quilted layers of cloth and batting.
A9: Plate | B9: Heavy Armor | C9: 18 | D9: 15 | E9: Disadvantage | F9: 1,500 GP | G9: 1500 | H9: 65 lbs | I9: 65 | J9: D&D Beyond Basic Rules | K9: Plate consists of shaped, interlocking metal plates to cover the entire body. A suit of plate includes gauntlets, heavy leather boots, a visored helmet, and thick layers of padding underneath the armor. Buckles and straps distribute the weight over the body.
A10: Ring Mail | B10: Heavy Armor | C10: 14 | E10: Disadvantage | F10: 30 GP | G10: 30 | H10: 40 lbs | I10: 40 | J10: D&D Beyond Basic Rules | K10: This armor is leather armor with heavy rings sewn into it. The rings help reinforce the armor against blows from swords and axes. Ring mail is inferior to chain mail, and it's usually worn only by those who can't afford better armor.
A11: Scale Mail | B11: Medium Armor | C11: 14 + Dex modifier (max 2) | E11: Disadvantage | F11: 50 GP | G11: 50 | H11: 45 lbs | I11: 45 | J11: D&D Beyond Basic Rules | K11: This armor consists of a coat and leggings (and perhaps a separate skirt) of leather covered with overlapping pieces of metal, much like the scales of a fish. The suit includes gauntlets.
A12: Shield | B12: Shield | C12: 2 | F12: 10 GP | G12: 10 | H12: 6 lbs | I12: 6 | J12: D&D Beyond Basic Rules | K12: Shields require the Utilize action to Don or Doff. You gain the Armor Class benefit of a Shield only if you have training with it.
A13: Spiked Armor | B13: Medium Armor | C13: 14 + Dex modifier (max 2) | E13: Disadvantage | F13: 75 GP | G13: 75 | H13: 45 lbs | I13: 45 | J13: D&D Beyond Basic Rules | K13: Spiked armor is a rare type of medium armor made by dwarves. It consists of a leather coat and leggings covered with spikes that are usually made of metal.
A14: Splint | B14: Heavy Armor | C14: 17 | D14: 15 | E14: Disadvantage | F14: 200 GP | G14: 200 | H14: 60 lbs | I14: 60 | J14: D&D Beyond Basic Rules | K14: This armor is made of narrow vertical strips of metal riveted to a backing of leather that is worn over cloth padding. Flexible chain mail protects the joints.
A15: Studded Leather | B15: Light Armor | C15: 12 + Dex modifier | F15: 45 GP | G15: 45 | H15: 13 lbs | I15: 13 | J15: D&D Beyond Basic Rules | K15: Made from tough but flexible leather, studded leather is reinforced with close-set rivets or spikes.
